Workbook

Sheet 需求追踪矩阵
A1: 序号 | B1: 角色 | C1: 业务流程 | D1: 用例编号 | E1: 用例名称 | F1: 需求编号 | G1: 需求类型 | H1: 验收方式（可观察结果） | I1: 负责人 | J1: 复核人 | K1: 阶段归属
A2: 1 | B2: 买家 | C2: 用户注册流程 | D2: UC-USER-001 | E2: 用户注册 | F2: FR-USER-001 | G2: 功能需求 | H2: 提交合法登录名与密码可注册成功，重复登录名返回冲突，响应不含密码或哈希 | I2: 方越 | J2: 王鹏宇 | K2: 项目I必须
A3: 2 | B3: 买家 | C3: 用户注册流程 | D3: UC-USER-001 | E3: 用户注册 | F3: SR-DATA-001 | G3: 安全需求 | H3: 检查数据库中不存在原始密码 | I3: 王鹏宇 | J3: 李陶然 | K3: 项目I必须
A4: 3 | B4: 买家 | C4: 用户注册流程 | D4: UC-USER-001 | E4: 用户注册 | F4: SR-SQL-001 | G4: 安全需求 | H4: 代码检查并执行 SQL 注入测试 | I4: 王鹏宇 | J4: 李陶然 | K4: 项目I必须
A5: 4 | B5: 买家、商户、管理员 | C5: 用户登录与退出流程 | D5: UC-USER-002 | E5: 用户登录 | F5: FR-USER-002 | G5: 功能需求 | H5: 正确凭据登录成功并返回有效令牌，错误凭据不得建立会话 | I5: 方越 | J5: 王鹏宇 | K5: 项目I必须
A6: 5 | B6: 买家、商户、管理员 | C6: 用户登录与退出流程 | D6: UC-USER-002 | E6: 用户登录 | F6: SR-INPUT-001 | G6: 安全需求 | H6: 提交空值、超长值和非法字符，系统应拒绝 | I6: 王鹏宇 | J6: 李陶然 | K6: 项目I必须
A7: 6 | B7: 买家、商户、管理员 | C7: 用户登录与退出流程 | D7: UC-USER-002 | E7: 用户登录 | F7: SR-AUTH-002 | G7: 安全需求 | H7: 连续输入5次错误密码，系统应提示账号锁定 | I7: 王鹏宇 | J7: 李陶然 | K7: 项目I必须
A8: 7 | B8: 买家、商户、管理员 | C8: 用户登录与退出流程 | D8: UC-USER-002 | E8: 用户登录 | F8: SR-LOG-001 | G8: 安全需求 | H8: 检查注册、登录和异常日志 | I8: 王鹏宇 | J8: 李陶然 | K8: 项目I必须
A9: 8 | B9: 买家、商户、管理员 | C9: 用户登录与退出流程 | D9: UC-USER-002 | E9: 用户登录 | F9: NFR-REL-001 | G9: 非功能需求 | H9: 模拟服务异常，前端不暴露堆栈信息或500页面 | I9: 张桐睿 | J9: 王陈俊 | K9: 项目I必须
A10: 9 | B10: 买家、商户、管理员 | C10: 用户登录与退出流程 | D10: UC-USER-004 | E10: 用户退出 | F10: FR-USER-003 | G10: 功能需求 | H10: 退出成功后再用原令牌访问受保护接口，应返回未认证 | I10: 方越 | J10: 王鹏宇 | K10: 项目I必须
A11: 10 | B11: 买家、商户、管理员 | C11: 用户登录与退出流程 | D11: UC-USER-004 | E11: 用户退出 | F11: SR-SESSION-001 | G11: 安全需求 | H11: 使用退出前的令牌再次访问，应返回未认证 | I11: 王鹏宇 | J11: 李陶然 | K11: 项目I必须
A12: 11 | B12: 买家、商户、管理员 | C12: 个人信息查询与修改流程 | D12: UC-USER-003 | E12: 查询个人信息 | F12: FR-USER-004 | G12: 功能需求 | H12: 仅返回本人资料且敏感字段脱敏，不接受客户端指定用户编号 | I12: 方越 | J12: 王鹏宇 | K12: 项目I必须
A13: 12 | B13: 买家、商户、管理员 | C13: 个人信息查询与修改流程 | D13: UC-USER-003 | E13: 查询个人信息 | F13: SR-AUTH-001 | G13: 安全需求 | H13: 修改请求中的用户编号，服务器应拒绝访问 | I13: 王鹏宇 | J13: 李陶然 | K13: 项目I必须
... A26: 25 | B26: 管理员 | C26: 平台审核与安全审计流程 | D26: UC-ADMIN-002 | E26: 账号封禁与审计日志 | F26: FR-ADMIN-002 | G26: 功能需求 | H26: 管理员可查询审计日志，且系统不提供修改或删除入口 | I26: 张桐睿 | J26: 王鹏宇 | K26: 项目I扩展

Sheet 统计概览
A1: CipherBook 在线书店 · 需求追踪矩阵 V1 · 统计概览
A2: 统计口径：本工作簿「需求追踪矩阵」表，每条需求登记 1 条主追踪条目；验收下限取自第 3 周任务书；需求/用例编号与《安全与非功能需求清单V1》《API对象清单V0.1》保持一致。
A3: 一、需求条数与验收下限
A4: 指标 | B4: 数量 | C4: 验收下限 | D4: 是否达标
A5: 功能需求条数（FR-*） | B5: =COUNTIF('需求追踪矩阵'!$F:$F,"FR-*") -> 16 | C5: 10 | D5: =IF(B5>=C5,"达标","不足") -> 达标
A6: 其中：用户管理核心需求（FR-USER-*） | B6: =COUNTIF('需求追踪矩阵'!$F:$F,"FR-USER-*") -> 6 | C6: 6 | D6: =IF(B6>=C6,"达标","不足") -> 达标
A7: 安全需求条数（SR-*） | B7: =COUNTIF('需求追踪矩阵'!$F:$F,"SR-*") -> 7 | C7: 6 | D7: =IF(B7>=C7,"达标","不足") -> 达标
A8: 安全与非功能需求合计（SR-* + NFR-*） | B8: =COUNTIF('需求追踪矩阵'!$F:$F,"SR-*")+COUNTIF('需求追踪矩阵'!$F:$F,"NFR-*") -> 9 | C8: 8 | D8: =IF(B8>=C8,"达标","不足") -> 达标
A9: 需求条目合计 | B9: =B5+B8 -> 25 | C9: 18 | D9: =IF(B9>=C9,"达标","不足") -> 达标
A11: 二、业务流程覆盖（第 3 周要求的 3 条核心流程 + 扩展流程）
A12: 业务流程 | B12: 关联需求条目数 | C12: 覆盖用例 | D12: 是否覆盖
A13: 用户注册流程 | B13: =COUNTIF('需求追踪矩阵'!$C:$C,$A13) -> 3 | C13: UC-USER-001 | D13: =IF(B13>0,"已覆盖","缺失") -> 已覆盖
A14: 用户登录与退出流程 | B14: =COUNTIF('需求追踪矩阵'!$C:$C,$A14) -> 7 | C14: UC-USER-002、UC-USER-004 | D14: =IF(B14>0,"已覆盖","缺失") -> 已覆盖
A15: 个人信息查询与修改流程 | B15: =COUNTIF('需求追踪矩阵'!$C:$C,$A15) -> 4 | C15: UC-USER-003、UC-USER-005、UC-USER-006 | D15: =IF(B15>0,"已覆盖","缺失") -> 已覆盖
A16: 浏览图书并加入购物车流程 | B16: =COUNTIF('需求追踪矩阵'!$C:$C,$A16) -> 5 | C16: UC-BOOK-001、UC-BOOK-002、UC-CART-001、UC-CART-002 | D16: =IF(B16>0,"已覆盖","缺失") -> 已覆盖
A17: 商户发布与维护图书流程 | B17: =COUNTIF('需求追踪矩阵'!$C:$C,$A17) -> 1 | C17: UC-MER-001 | D17: =IF(B17>0,"已覆盖","缺失") -> 已覆盖
A18: 订单创建与支付流程 | B18: =COUNTIF('需求追踪矩阵'!$C:$C,$A18) -> 3 | C18: UC-ORDER-001、UC-ORDER-002、UC-PAY-001 | D18: =IF(B18>0,"已覆盖","缺失") -> 已覆盖
A19: 平台审核与安全审计流程 | B19: =COUNTIF('需求追踪矩阵'!$C:$C,$A19) -> 2 | C19: UC-ADMIN-001、UC-ADMIN-002 | D19: =IF(B19>0,"已覆盖","缺失") -> 已覆盖
A20: 合计 | B20: =SUM(B13:B19) -> 25 | C20: — | D20: —
A22: 三、用例覆盖（每个用例至少关联 1 条需求）
A23: 用例编号 | B23: 用例名称 | C23: 关联需求条目数 | D23: 是否覆盖
A24: UC-USER-001 | B24: 用户注册 | C24: =COUNTIF('需求追踪矩阵'!$D:$D,$A24) -> 3 | D24: =IF(C24>0,"已覆盖","缺失") -> 已覆盖
A25: UC-USER-002 | B25: 用户登录 | C25: =COUNTIF('需求追踪矩阵'!$D:$D,$A25) -> 5 | D25: =IF(C25>0,"已覆盖","缺失") -> 已覆盖
A26: UC-USER-003 | B26: 查询个人信息 | C26: =COUNTIF('需求追踪矩阵'!$D:$D,$A26) -> 2 | D26: =IF(C26>0,"已覆盖","缺失") -> 已覆盖
A27: UC-USER-004 | B27: 用户退出 | C27: =COUNTIF('需求追踪矩阵'!$D:$D,$A27) -> 2 | D27: =IF(C27>0,"已覆盖","缺失") -> 已覆盖
A28: UC-USER-005 | B28: 修改个人信息 | C28: =COUNTIF('需求追踪矩阵'!$D:$D,$A28) -> 1 | D28: =IF(C28>0,"已覆盖","缺失") -> 已覆盖
A29: UC-USER-006 | B29: 修改密码 | C29: =COUNTIF('需求追踪矩阵'!$D:$D,$A29) -> 1 | D29: =IF(C29>0,"已覆盖","缺失") -> 已覆盖
A30: UC-BOOK-001 | B30: 浏览与搜索图书 | C30: =COUNTIF('需求追踪矩阵'!$D:$D,$A30) -> 2 | D30: =IF(C30>0,"已覆盖","缺失") -> 已覆盖
A31: UC-BOOK-002 | B31: 查看图书详情 | C31: =COUNTIF('需求追踪矩阵'!$D:$D,$A31) -> 1 | D31: =IF(C31>0,"已覆盖","缺失") -> 已覆盖
A32: UC-CART-001 | B32: 查询购物车 | C32: =COUNTIF('需求追踪矩阵'!$D:$D,$A32) -> 1 | D32: =IF(C32>0,"已覆盖","缺失") -> 已覆盖
A33: UC-CART-002 | B33: 加入购物车 | C33: =COUNTIF('需求追踪矩阵'!$D:$D,$A33) -> 1 | D33: =IF(C33>0,"已覆盖","缺失") -> 已覆盖
A34: UC-MER-001 | B34: 维护本店图书 | C34: =COUNTIF('需求追踪矩阵'!$D:$D,$A34) -> 1 | D34: =IF(C34>0,"已覆盖","缺失") -> 已覆盖
A35: UC-ORDER-001 | B35: 创建与查询订单 | C35: =COUNTIF('需求追踪矩阵'!$D:$D,$A35) -> 1 | D35: =IF(C35>0,"已覆盖","缺失") -> 已覆盖
... A39: UC-PAY-001 | B39: 支付请求与回调 | C39: =COUNTIF('需求追踪矩阵'!$D:$D,$A39) -> 1 | D39: =IF(C39>0,"已覆盖","缺失") -> 已覆盖
A40: 合计 | B40: — | C40: =SUM(C24:C39) -> 25 | D40: —
A42: 四、角色覆盖（用例图须覆盖买家、商户、管理员与支付机构）
A43: 角色 | B43: 关联需求条目数 | C43: 是否覆盖 | D43: 说明
A44: 买家 | B44: =COUNTIF('需求追踪矩阵'!$B:$B,"*"&$A44&"*") -> 20 | C44: =IF(B44>0,"已覆盖","缺失") -> 已覆盖 | D44: 平台内部业务角色
A45: 商户 | B45: =COUNTIF('需求追踪矩阵'!$B:$B,"*"&$A45&"*") -> 13 | C45: =IF(B45>0,"已覆盖","缺失") -> 已覆盖 | D45: 平台内部业务角色
A46: 管理员 | B46: =COUNTIF('需求追踪矩阵'!$B:$B,"*"&$A46&"*") -> 13 | C46: =IF(B46>0,"已覆盖","缺失") -> 已覆盖 | D46: 平台内部业务角色
...
